<?xml version="1.0"?>
<robot name="bot">
    
    <link name="base_link">
        <visual>
            <geometry>
                <box size="0.385 0.385 0.33"/>
            </geometry>
            <material name="red">
                <color rgba="0 0.0 1.0 1"/>
            </material>
        </visual>
        <collision>
            <geometry>
                <box size="0.385 0.385 0.33"/>
            </geometry>
        </collision>
        <inertial>
            <mass value="1.0"/>
            <inertia ixx="0.021427083" ixy="0" ixz="0" iyy="0.024704167" iyz="0.0" izz="0.021427083"/>
        </inertial>
        
    </link>


    <link name="front_caster_of_wheel">
        <visual>
            <geometry>
                <box size="0.08 0.08 0.08"/>
            </geometry>
            <material name="green">
                <color rgba="0.9 0.0 0.0 1"/>   
            </material>
        </visual>
        <collision>
            <geometry>
                <box size="0.08 0.08 0.08"/>
            </geometry>
        </collision>
        <inertial>
            <mass value="0.1"/>
            <inertia ixx="0.0001067" ixy="0" ixz="0" iyy="0.0001067" iyz="0.0" izz="0.0001067"/>
        </inertial>
    </link>
    <joint name="front_caster_of_wheel_joint" type="continuous">
    <axis xyz="0.0 0.0 1"/> 
    <parent link="base_link"/>
    <child link="front_caster_of_wheel"/>
    <origin xyz="0.1925 0.0 -0.165" rpy="0.0 0.0 0.0"/>
    </joint>

    <link name="front_wheel">
        <visual>
            <geometry>
                <cylinder radius="0.015" length="0.015"/>
            </geometry>
            <material name="black">
                
            </material>

        </visual>
        <collision>
            <geometry>
                <cylinder radius="0.015" length="0.05"/>
            </geometry>
        </collision>
        <inertial>
            <mass value="0.1"/>
            <inertia ixx="7.5e-06" ixy="0" ixz="0" iyy="7.5e-06" iyz="0.0" izz="1.1249e-05"/>
        </inertial>
    </link>

    <joint name="front_wheel_joint" type="continuous">
        <axis xyz="0.0 0.0 1"/>
        <parent link="front_caster_of_wheel"/>
        <child link="front_wheel"/>
        <origin xyz="0.00 0.0 -0.055" rpy="-1.5708 0.0 0.0"/>
        
    </joint>


    <link name="back_caster_of_wheel">
        <visual>
            <geometry>
                <box size="0.08 0.08 0.08"/>
            </geometry>
            <material name="green">
                <color rgba="0.9 0.0 0.0 1"/>   
            </material>
        </visual>
        <collision>
            <geometry>
                <box size="0.08 0.08 0.08"/>
            </geometry>
        </collision>
        <inertial>
            <mass value="0.1"/>
            <inertia ixx="0.0001067" ixy="0" ixz="0" iyy="0.0001067" iyz="0.0" izz="0.0001067"/>
        </inertial>
    </link>
    <joint name="back_caster_of_wheel_joint" type="continuous">
    <axis xyz="0.0 0.0 1"/> 
    <parent link="base_link"/>
    <child link="back_caster_of_wheel"/>
    <origin xyz="-0.1925 0.0 -0.165" rpy="0.0 0.0 0.0"/>
    </joint>

    <link name="back_wheel">
        <visual>
            <geometry>
                <cylinder radius="0.015" length="0.015"/>
            </geometry>
            <material name="black">
                
            </material>

        </visual>
        <collision>
            <geometry>
                <cylinder radius="0.015" length="0.015"/>
            </geometry>
        </collision>
        <inertial>
            <mass value="0.1"/>
            <inertia ixx="7.5e-06" ixy="0" ixz="0" iyy="7.5e-06" iyz="0.0" izz="1.1249e-05"/>
        </inertial>
    </link>

    <joint name="back_wheel_joint" type="continuous">
        <axis xyz="0.0 0.0 1"/>
        <parent link="back_caster_of_wheel"/>
        <child link="back_wheel"/>
        <origin xyz="0.00 0.0 -0.055" rpy="-1.5708 0.0 0.0"/>
        
    </joint>    


    <link name="right_wheel">
        <visual>
            <geometry>
                <cylinder radius="0.055" length="0.045"/>
            </geometry>
            <material name="black">
                <color rgba="0.0 0.0 0.0 1"/>
            </material>

        </visual>
        <collision>
            <geometry>
                <cylinder radius="0.055" length="0.045"/>
            </geometry>
        </collision>
        <inertial>
            <mass value="0.1"/>
            <inertia ixx="9.249e-05" ixy="0" ixz="0" iyy="9.249e-05" iyz="0.0" izz="0.000151250"/>        </inertial>
    </link>

    <joint name="right_wheel_joint" type="continuous">
        <axis xyz="0.0 0.0 1"/>
        <parent link="base_link"/>
        <child link="right_wheel"/>
        <origin xyz="0.0 -0.1700 -0.180" rpy="-1.5708 0.0 0.0"/>
    </joint>

    <link name="left_wheel">
        <visual>
            <geometry>
                <cylinder radius="0.055" length="0.045"/>
            </geometry>
            <material name="black">
                <color rgba="0.0 0.0 0.0 1"/>
            </material>

        </visual>
        <collision>
            <geometry>
                <cylinder radius="0.055" length="0.045"/>
            </geometry>
        </collision>
        <inertial>
            <mass value="0.1"/>
            <inertia ixx="9.249e-05" ixy="0" ixz="0" iyy="9.249e-05" iyz="0.0" izz="0.000151250"/>        </inertial>
    </link>

    <joint name="left_wheel_joint" type="continuous">
        <axis xyz="0.0 0.0 1"/>
        <parent link="base_link"/>
        <child link="left_wheel"/>
        <origin xyz="0.0 0.1700 -0.180" rpy="-1.5708 0.0 0.0"/>
    </joint>
    
    <link name="laser_scanner">
        <visual>
            <geometry>
                <box size="0.07 0.07 0.07"/>
            </geometry>
        </visual>

        <collision>
            <geometry>
                <box size="0.07 0.07 0.07"/>
            </geometry>
        </collision>

        <inertial>
            <mass value="0.01"/>
            <inertia ixx="8.167e-06" ixy="0" ixz="0.0" iyy="8.167e-06" iyz="0.0" izz="8.167e-06"/>
        </inertial>
    </link>

    <joint name="laser_scanner_joint" type="fixed">
        <axis xyz="0.0 1 0.0"/>
        <parent link="base_link"/>
        <child link="laser_scanner"/>
        <origin xyz="0.0 0.0 0.200" rpy="0.0 0.0 0.0"/>
    </joint>


    <link name="kinect_scanner">
        <visual>
            <geometry>
                <box size="0.05 0.28 0.034"/>
            </geometry>
        </visual>

        <collision>
            <geometry>
                <box size="0.05 0.28 0.034"/>
            </geometry>
        </collision>
    </link>

    <joint name="kinect_scanner_joint" type="fixed">
        <axis xyz="0.0 1 0.0"/>
        <parent link="base_link"/>
        <child link="kinect_scanner"/>
        <origin xyz="0.169 0.0 0.07" rpy="0.0 0.0 0.0"/>
    </joint>


    <gazebo reference="laser_scanner">
        <sensor type="ray" name="laser">
            <pose>0 0 0 0 0 0</pose>
            <visualize>true</visualize>
            <update_rate>40</update_rate>
            <ray>
                <scan>
                    <horizontal>
                        <samples>360</samples>
                        <resolution>1</resolution>
                        <min_angle>0</min_angle>
                        <max_angle>6.292</max_angle>
                    </horizontal>
                </scan>
                <range>
                    <min>0.1</min>
                    <max>7</max>
                    <resolution>0.1</resolution>
                </range>
            </ray>
            <plugin name="Lidar" filename="libgazebo_ros_laser.so">
                <topicName>laser/scan</topicName>
                <frameName>laser_scanner</frameName>
            </plugin>
        </sensor>
    </gazebo>

    <gazebo reference="kinect_scanner">
        <sensor type="ray" name="laser2">
            <pose>0 0 0 0 0 0</pose>
            <visualize>true</visualize>
            <update_rate>40</update_rate>
            <ray>
                <scan>
                    <horizontal>
                        <samples>640</samples>
                        <resolution>1</resolution>
                        <min_angle>-0.524</min_angle>
                        <max_angle>0.524</max_angle>
                    </horizontal>
                </scan>
                <range>
                    <min>0.1</min>
                    <max>7</max>
                    <resolution>0.1</resolution>
                </range>
            </ray>
            <plugin name="Lidar" filename="libgazebo_ros_laser.so">
                <topicName>laserscan_kinect/scan</topicName>
                <frameName>kinect_scanner</frameName>
            </plugin>
        </sensor>
    </gazebo>

    <gazebo>
        <plugin name="explorer_bot_controller"   filename="libgazebo_ros_diff_drive.so">
            <leftJoint>left_wheel_joint</leftJoint>
            <rightJoint>right_wheel_joint</rightJoint>
            <legacyMode>false</legacyMode>
            <robotBaseFrame>base_link</robotBaseFrame>
            <wheelSeparation>0.340</wheelSeparation>
            <wheelDiameter>0.11</wheelDiameter>
            <publishWheelJointState>true</publishWheelJointState>
        </plugin>
        
    </gazebo>
    <gazebo>
        <plugin name="joint_state_publisher"
                filename="libgazebo_ros_joint_state_publisher.so">
            <jointName>front_caster_of_wheel_joint, front_wheel_joint, back_caster_of_wheel_joint, back_wheel_joint</jointName>
        </plugin>
    </gazebo>


    <gazebo reference="base_link">
        <material>Gazebo/Blue</material>
    </gazebo>

    <gazebo reference="front_caster_of_wheel">
        <material>Gazebo/Red</material>
      </gazebo>
      <gazebo reference="back_caster_of_wheel">
        <material>Gazebo/Red</material>
      </gazebo>
      <gazebo reference="front_wheel">
        <material>Gazebo/Black</material>
      </gazebo>
      <gazebo reference="back_wheel">
        <material>Gazebo/Black</material>
      </gazebo>
      <gazebo reference="left_wheel">
        <material>Gazebo/Black</material>
      </gazebo>
      <gazebo reference="right_wheel">
        <material>Gazebo/Black</material>
      </gazebo>


</robot>
