<?xml version="1.0"?>
<robot name="bot">
    
    <link name="base_link">
        <visual>
            <geometry>
                <box size="0.385 0.385 0.33"/>
            </geometry>
            <material name="red">
                <color rgba="0 0.0 1.0 1"/>
            </material>
        </visual>
        <collision>
            <geometry>
                <box size="0.385 0.385 0.33"/>
            </geometry>
        </collision>
    </link>


    <link name="front_caster_of_wheel">
        <visual>
            <geometry>
                <box size="0.08 0.08 0.08"/>
            </geometry>
            <material name="green">
                <color rgba="0.9 0.0 0.0 1"/>   
            </material>
        </visual>
        <collision>
            <geometry>
                <box size="0.08 0.08 0.08"/>
            </geometry>
        </collision>
    </link>
    <joint name="front_caster_of_wheel_joint" type="continuous">
    <axis xyz="0.0 0.0 1"/> 
    <parent link="base_link"/>
    <child link="front_caster_of_wheel"/>
    <origin xyz="0.1925 0.0 -0.165" rpy="0.0 0.0 0.0"/>
    </joint>

    <link name="front_wheel">
        <visual>
            <geometry>
                <cylinder radius="0.015" length="0.01"/>
            </geometry>
            <material name="black">
                
            </material>

        </visual>
        <collision>
            <geometry>
                <cylinder radius="0.015" length="0.01"/>
            </geometry>
        </collision>
    </link>

    <joint name="front_wheel_joint" type="continuous">
        <axis xyz="0.0 0.0 1"/>
        <parent link="front_caster_of_wheel"/>
        <child link="front_wheel"/>
        <origin xyz="0.00 0.0 -0.055" rpy="-1.5708 0.0 0.0"/>
        
    </joint>


    <link name="back_caster_of_wheel">
        <visual>
            <geometry>
                <box size="0.08 0.08 0.08"/>
            </geometry>
            <material name="green">
                <color rgba="0.9 0.0 0.0 1"/>   
            </material>
        </visual>
        <collision>
            <geometry>
                <box size="0.08 0.08 0.08"/>
            </geometry>
        </collision>
    </link>
    <joint name="back_caster_of_wheel_joint" type="continuous">
    <axis xyz="0.0 0.0 1"/> 
    <parent link="base_link"/>
    <child link="back_caster_of_wheel"/>
    <origin xyz="-0.1925 0.0 -0.165" rpy="0.0 0.0 0.0"/>
    </joint>

    <link name="back_wheel">
        <visual>
            <geometry>
                <cylinder radius="0.015" length="0.01"/>
            </geometry>
            <material name="black">
                
            </material>

        </visual>
        <collision>
            <geometry>
                <cylinder radius="0.015" length="0.01"/>
            </geometry>
        </collision>
    </link>

    <joint name="back_wheel_joint" type="continuous">
        <axis xyz="0.0 0.0 1"/>
        <parent link="back_caster_of_wheel"/>
        <child link="back_wheel"/>
        <origin xyz="0.00 0.0 -0.055" rpy="-1.5708 0.0 0.0"/>
        
    </joint>    

    <link name="right_wheel">
        <visual>
            <geometry>
                <cylinder radius="0.055" length="0.045"/>
            </geometry>
            <material name="black">
                <color rgba="0.0 0.0 0.0 1"/>
            </material>

        </visual>
        <collision>
            <geometry>
                <cylinder radius="0.055" length="0.045"/>
            </geometry>
        </collision>
    </link>

    <joint name="right_wheel_joint" type="continuous">
        <axis xyz="0.0 0.0 1"/>
        <parent link="base_link"/>
        <child link="right_wheel"/>
        <origin xyz="0.0 -0.1700 -0.180" rpy="-1.5708 0.0 0.0"/>
    </joint>

    <link name="left_wheel">
        <visual>
            <geometry>
                <cylinder radius="0.055" length="0.045"/>
            </geometry>
            <material name="black">
                <color rgba="0.0 0.0 0.0 1"/>
            </material>

        </visual>
        <collision>
            <geometry>
                <cylinder radius="0.055" length="0.045"/>
            </geometry>
        </collision>
    </link>

    <joint name="left_wheel_joint" type="continuous">
        <axis xyz="0.0 0.0 1"/>
        <parent link="base_link"/>
        <child link="left_wheel"/>
        <origin xyz="0.0 0.1700 -0.180" rpy="-1.5708 0.0 0.0"/>
    </joint>

    <link name="laser_scanner">
        <visual>
            <geometry>
                <box size="0.07 0.07 0.07"/>
            </geometry>
        </visual>

        <collision>
            <geometry>
                <box size="0.07 0.07 0.07"/>
            </geometry>
        </collision>
    </link>

    <joint name="laser_scanner_joint" type="fixed">
        <axis xyz="0.0 1 0.0"/>
        <parent link="base_link"/>
        <child link="laser_scanner"/>
        <origin xyz="0.0 0.0 0.200" rpy="0.0 0.0 0.0"/>
    </joint>

    <link name="kinect_scanner">
        <visual>
            <geometry>
                <box size="0.05 0.28 0.034"/>
            </geometry>
        </visual>

        <collision>
            <geometry>
                <box size="0.05 0.28 0.034"/>
            </geometry>
        </collision>
    </link>

    <joint name="kinect_scanner_joint" type="fixed">
        <axis xyz="0.0 1 0.0"/>
        <parent link="base_link"/>
        <child link="kinect_scanner"/>
        <origin xyz="0.169 0.0 0.07" rpy="0.0 0.0 0.0"/>
    </joint>

    <link name="imu">
        <visual>
            <geometry>
                <box size="0.027 0.02 0.004"/>
            </geometry>
        </visual>

        <collision>
            <geometry>
                <box size="0.027 0.02 0.004"/>
            </geometry>
        </collision>
    </link>

    <joint name="base_link_to_imu_link" type="fixed">
        <axis xyz="0.0 1 0.0"/>
        <parent link="base_link"/>
        <child link="imu"/>
        <origin xyz="-0.1125 -0.095 0.165" rpy="0.0 0.0 0.0"/>
    </joint>

</robot>
